<?xml version="1.0" encoding="utf-8"?>
<!-- This URDF was automatically created by SolidWorks to URDF Exporter! Originally created by Stephen Brawner (brawner@gmail.com) 
     Commit Version: 1.6.0-1-g15f4949  Build Version: 1.6.7594.29634
     For more information, please see http://wiki.ros.org/sw_urdf_exporter -->
<robot
  name="model_robot">
  <link
    name="base_link">
    <inertial>
      <origin
        xyz="0.0081111 0.0012491 0.041007"
        rpy="0 0 0" />
      <mass
        value="0.1898" />
      <inertia
        ixx="0.00020491"
        ixy="3.6538E-07"
        ixz="-1.3495E-05"
        iyy="0.00024936"
        iyz="9.5605E-08"
        izz="0.00038879" />
    </inertial>
    <visual>
      <origin
        xyz="0 0 0"
        rpy="0 0 0" />
      <geometry>
        <mesh
          filename="../meshes/base_link.STL" />
      </geometry>
      <material
        name="">
        <color
          rgba="0.79216 0.81961 0.93333 1" />
      </material>
    </visual>
    <collision>
      <origin
        xyz="0 0 0"
        rpy="0 0 0" />
      <geometry>
        <mesh
          filename="../meshes/base_link.STL" />
      </geometry>
    </collision>
  </link>
  <link
    name="roda_kanan">
    <inertial>
      <origin
        xyz="0.034939 0.077797 0.01425"
        rpy="0 0 0" />
      <mass
        value="0.029734" />
      <inertia
        ixx="1.2291E-05"
        ixy="8.982E-11"
        ixz="3.4873E-11"
        iyy="2.0379E-05"
        iyz="-1.0991E-12"
        izz="1.2291E-05" />
    </inertial>
    <visual>
      <origin
        xyz="0 0 0"
        rpy="0 0 0" />
      <geometry>
        <mesh
          filename="../meshes/roda_kanan.STL" />
      </geometry>
      <material
        name="">
        <color
          rgba="0.79216 0.81961 0.93333 1" />
      </material>
    </visual>
    <collision>
      <origin
        xyz="0 0 0"
        rpy="0 0 0" />
      <geometry>
        <mesh
          filename="../meshes/roda_kanan.STL" />
      </geometry>
    </collision>
  </link>
  <joint
    name="joint_kanan"
    type="continuous">
    <origin
      xyz="0.034939 0.087797 0.01425"
      rpy="0 0 0" />
    <parent
      link="base_link" />
    <child
      link="roda_kanan" />
    <axis
      xyz="0 1 0" />
  </joint>
  <link
    name="roda_kiri">
    <inertial>
      <origin
        xyz="0.034939 -0.075003 0.01425"
        rpy="0 0 0" />
      <mass
        value="0.029734" />
      <inertia
        ixx="1.2291E-05"
        ixy="6.0955E-11"
        ixz="-1.7196E-10"
        iyy="2.0379E-05"
        iyz="6.598E-11"
        izz="1.2291E-05" />
    </inertial>
    <visual>
      <origin
        xyz="0 0 0"
        rpy="0 0 0" />
      <geometry>
        <mesh
          filename="../meshes/roda_kiri.STL" />
      </geometry>
      <material
        name="">
        <color
          rgba="0.79216 0.81961 0.93333 1" />
      </material>
    </visual>
    <collision>
      <origin
        xyz="0 0 0"
        rpy="0 0 0" />
      <geometry>
        <mesh
          filename="../meshes/roda_kiri.STL" />
      </geometry>
    </collision>
  </link>
  <joint
    name="joint_kiri"
    type="continuous">
    <origin
      xyz="0.034939 -0.085003 0.01425"
      rpy="0 0 0" />
    <parent
      link="base_link" />
    <child
      link="roda_kiri" />
    <axis
      xyz="0 1 0" />
  </joint>
</robot>
